<?xml version="1.0"?>
<robot name="my_robot7">

  <material name="green">
    <color rgba="0.0 1.0 0.0 1.0"/>
  </material>
 
  <material name="grey">
    <color rgba="0.2 0.2 0.2 1.0"/>
  </material>
  
  <link name="base_link">
    <visual>
      <geometry>
        <box size="0.4 0.4 0.1"/>
      </geometry>
      <origin xyz="0 0 0.05" rpy="0 0 0"/>
      <material name="green"/>
    </visual>
     <collision>
      <geometry>
        <box size="0.4 0.4 0.1"/>
      </geometry>
      <origin xyz="0 0 0.05" rpy="0 0 0"/>
    </collision>
  </link>
  
  <link name="shoulder_link">
    <visual>
      <geometry>
        <cylinder radius="0.1" length="0.5"/>
      </geometry>
      <origin xyz="0 0 0.25" rpy="0 0 1.57"/>
      <material name="grey"/>
    </visual>
    <collision>
      <geometry>
        <cylinder radius="0.1" length="0.5"/>
      </geometry>
      <origin xyz="0 0 0.25" rpy="0 0 0"/>
    </collision>
  </link>
  
  <link name="arm_link">
    <visual>
      <geometry>
        <cylinder radius="0.05" length="1.0"/>
      </geometry>
      <origin xyz="0 0 0.5" rpy="0 0 1.57"/>
      <material name="green"/>
    </visual>
    <collision>
      <geometry>
        <cylinder radius="0.05" length="0.6"/>
      </geometry>
      <origin xyz="0 0 0.3" rpy="0 0 0"/>
    </collision>
  </link>
  
  <link name="elbow_link">
    <visual>
      <geometry>
        <cylinder radius="0.05" length="0.1"/>
      </geometry>
      <origin xyz="0 0 0.05" rpy="0 0 1.57"/>
      <material name="grey"/>
    </visual>
    <collision>
      <geometry>
        <cylinder radius="0.05" length="0.1"/>
      </geometry>
      <origin xyz="0 0 0.05" rpy="0 0 0"/>
    </collision>
  </link>
  
  <link name="forearm_link">
    <visual>
      <geometry>
        <cylinder radius="0.05" length="0.5"/>
      </geometry>
      <origin xyz="0 0 0.25" rpy="0 0 1.57"/>
      <material name="green"/>
    </visual>
    <collision>
      <geometry>
        <cylinder radius="0.05" length="0.5"/>
      </geometry>
      <origin xyz="0 0 0.25" rpy="0 0 0"/>
    </collision>
  </link>

  <link name="wrist_link">
    <visual>
      <geometry>
        <box size="0.05 0.05 0.1"/>
      </geometry>
      <origin xyz="0 0 0.05" rpy="0 0 1.57"/>
      <material name="grey"/>
    </visual>
    <collision>
      <geometry>
        <box size="0.05 0.05 0.1"/>
      </geometry>
      <origin xyz="0 0 0.05" rpy="0 0 0"/>
    </collision>
  </link>

  <link name="hand_link">
    <visual>
      <geometry>
        <box size="0.02 0.02 0.02"/>
      </geometry>
      <origin xyz="0 0 0.01" rpy="0 0 1.57"/>
      <material name="green"/>
    </visual>
    <collision>
      <geometry>
        <box size="0.02 0.02 0.02"/>
      </geometry>
      <origin xyz="0 0 0.01" rpy="0 0 0"/>
    </collision>
  </link>

 <link name="extra_link">
    <visual>
      <geometry>
        <cylinder radius="0.05" length="0.5"/>
      </geometry>
      <origin xyz="0 0 0.25" rpy="0 0 1.57"/>
      
    </visual>
    <collision>
      <geometry>
        <box size="0.02 0.02 0.02"/>
      </geometry>
      <origin xyz="0 0 0.01" rpy="0 0 0"/>
    </collision>
  </link>

  <link name="tool_link">
  </link>

  <joint name="joint_1" type="revolute">
     <limit effort="1000.0" lower="-3.14" upper="3.14" velocity="1.0"/>
     <parent link="base_link"/>
     <child link="shoulder_link"/>
     <origin xyz="0 0 0.1" rpy="0 0 0"/>
     <axis xyz="0 0 1"/>
  </joint>  
  
  <joint name="joint_2" type="revolute">
     <limit effort="1000.0" lower="-1.57" upper="1.57" velocity="1.0"/>
     <parent link="shoulder_link"/>
     <child link="arm_link"/>
     <origin xyz="0 0 0.5" rpy="0 0 0"/>
     <axis xyz="1 0 0"/>
  </joint>

  <joint name="joint_7" type="revolute">
     <limit effort="1000.0" lower="-3.14" upper="3.14" velocity="1.0"/>
     <parent link="arm_link"/>
     <child link="extra_link"/>
     <origin xyz="0 0 1.0" rpy="0 0 0"/>
     <axis xyz="0 0 1"/>
  </joint>
  
  <joint name="joint_3" type="revolute">
     <limit effort="1000.0" lower="-1.57" upper="1.57" velocity="1.0"/>
     <parent link="extra_link"/>
     <child link="elbow_link"/>
     <origin xyz="0 0 0.5" rpy="0 0 0"/>
     <axis xyz="1 0 0"/>
  </joint>   
  
  <joint name="joint_4" type="revolute">
     <limit effort="1000.0" lower="-3.14" upper="3.14" velocity="1.0"/>
     <parent link="elbow_link"/>
     <child link="forearm_link"/>
     <origin xyz="0 0 0.1" rpy="0 0 0"/>
     <axis xyz="0 0 1"/>
  </joint>
  
  <joint name="joint_5" type="revolute">
     <limit effort="1000.0" lower="-1.57" upper="1.57" velocity="1.0"/>
     <parent link="forearm_link"/>
     <child link="wrist_link"/>
     <origin xyz="0 0 0.5" rpy="0 0 0"/>
     <axis xyz="1 0 0"/>
  </joint>
  
   <joint name="joint_6" type="continuous">
     <parent link="wrist_link"/>
     <child link="hand_link"/>
     <origin xyz="0 0 0.1" rpy="0 0 0"/>
     <axis xyz="0 0 1"/>
  </joint>

  <joint name="hand_tool_joint" type="fixed">
    <parent link="hand_link"/>
    <child link="tool_link"/>
    <origin xyz="0 0 0" rpy="0 0 0"/>
  </joint>
   
  </robot>
